### **Java Exception Handling Scenarios and Their Behavior**

#### **1. `try` ‚Äì `catch` ‚Äì `finally`**

- **`try`** block: Contains code that may cause an exception.
- **`catch`** block: Handles the exception.
- **`finally`** block: Always executes (whether an exception occurs or not).

```java
public class TryCatchFinallyExample {
    public static void main(String[] args) {
        try {
            System.out.println("Inside try block");
            int result = 10 / 0;  // ArithmeticException
        } catch (ArithmeticException e) {
            System.out.println("Exception caught: " + e);
        } finally {
            System.out.println("Finally block always executes");
        }
    }
}
```

**Output:**

```
Inside try block
Exception caught: java.lang.ArithmeticException: / by zero
Finally block always executes
```

üëâ **`finally` executes no matter what.**

---

#### **2. Multiple `try` ‚Äì Corresponding `catch`**

Each `try` block **must have at least one corresponding `catch` or `finally` block**.

```java
public class MultipleTryCatchExample {
    public static void main(String[] args) {
        try {
            System.out.println("First try block");
            int a = 10 / 0;  // ArithmeticException
        } catch (ArithmeticException e) {
            System.out.println("First Exception caught: " + e);
        }

        try {
            System.out.println("Second try block");
            int arr[] = new int[2];
            arr[5] = 10;  // ArrayIndexOutOfBoundsException
        } catch (ArrayIndexOutOfBoundsException e) {
            System.out.println("Second Exception caught: " + e);
        }
    }
}
```

**Output:**

```
First try block
First Exception caught: java.lang.ArithmeticException: / by zero
Second try block
Second Exception caught: java.lang.ArrayIndexOutOfBoundsException: Index 5 out of bounds for length 2
```

üëâ **Each `try` block must have a corresponding `catch` (or `finally`).**

---

#### **3. Single `try` ‚Äì Multiple `catch`**

A single `try` block can have multiple `catch` blocks to handle different exceptions. The **first matching `catch` block** executes.

```java
public class MultipleCatchExample {
    public static void main(String[] args) {
        try {
            int a = 10 / 0;  // ArithmeticException
        } catch (ArithmeticException e) {
            System.out.println("Arithmetic Exception caught");
        } catch (Exception e) {  // Parent class should be last
            System.out.println("General Exception caught");
        }
    }
}
```

**Output:**

```
Arithmetic Exception caught
```

üëâ **If multiple `catch` blocks match, the first one executes.**

üö® **Rule:** Always catch **specific exceptions first**, followed by **generic ones (Exception class)**.

```java
try {  
    int a = 10 / 0;
} catch (Exception e) {  
    System.out.println("General Exception caught");
} catch (ArithmeticException e) {  // ‚ùå ERROR: Unreachable code
    System.out.println("Arithmetic Exception caught");
}
```

**Compilation Error:** _Unreachable catch block for ArithmeticException_.

---

#### **4. `try` Block Without a Corresponding `catch`**

A `try` block **must have either `catch` or `finally`**. Otherwise, it results in a **compilation error**.

```java
public class TryWithoutCatchExample {
    public static void main(String[] args) {
        try {
            int a = 10 / 0;
        }
        System.out.println("Outside try block"); // ‚ùå COMPILATION ERROR
    }
}
```

**Compilation Error:**

```
Exception handling with try must have catch or finally
```

‚úÖ **Solution:** Use `finally`

```java
try {
    int a = 10 / 0;
} finally {
    System.out.println("Finally block executes");
}
```

---

#### **5. Exception Occurs Inside `catch` Block**

If an exception occurs inside a `catch` block, and it is **not handled**, it will propagate up the call stack and **terminate the program**.

```java
public class ExceptionInCatchExample {
    public static void main(String[] args) {
        try {
            int a = 10 / 0;
        } catch (ArithmeticException e) {
            System.out.println("Handling exception...");
            int b = 5 / 0;  // New exception in catch block
        }
        System.out.println("End of program");  // ‚ùå Never executes
    }
}
```

**Output:**

```
Handling exception...
Exception in thread "main" java.lang.ArithmeticException: / by zero
```

üëâ **Solution:** Handle the exception inside another `try-catch` block:

```java
try {
    int a = 10 / 0;
} catch (ArithmeticException e) {
    try {
        int b = 5 / 0;  // New exception inside catch
    } catch (Exception ex) {
        System.out.println("Exception inside catch handled: " + ex);
    }
}
System.out.println("End of program");
```

**Output:**

```
Exception inside catch handled: java.lang.ArithmeticException: / by zero
End of program
```

---

#### **6. Exception Occurs Inside `finally` Block**

If an exception occurs inside `finally` and is not handled, it **overrides any previous exception from `try` or `catch`**.

```java
public class ExceptionInFinallyExample {
    public static void main(String[] args) {
        try {
            int a = 10 / 0;
        } catch (ArithmeticException e) {
            System.out.println("Exception caught: " + e);
        } finally {
            System.out.println("Finally block executing...");
            int b = 5 / 0;  // Exception in finally
        }
    }
}
```

**Output:**

```
Exception caught: java.lang.ArithmeticException: / by zero
Finally block executing...
Exception in thread "main" java.lang.ArithmeticException: / by zero
```

üëâ **Solution:** Handle exception in `finally`

```java
finally {
    try {
        int b = 5 / 0;
    } catch (Exception e) {
        System.out.println("Handled exception in finally: " + e);
    }
}
```

---

#### **7. Exception Occurs Outside `catch` Block**

If an exception occurs **outside of any `try-catch` block**, the program **terminates immediately**.

```java
public class ExceptionOutsideCatch {
    public static void main(String[] args) {
        int a = 10 / 0;  // No try-catch, program crashes
        System.out.println("This line will not execute");
    }
}
```

**Output:**

```
Exception in thread "main" java.lang.ArithmeticException: / by zero
```

üëâ **Solution:** Wrap in `try-catch`

```java
try {
    int a = 10 / 0;
} catch (ArithmeticException e) {
    System.out.println("Exception handled: " + e);
}
System.out.println("Program continues...");
```

**Output:**

```
Exception handled: java.lang.ArithmeticException: / by zero
Program continues...
```

---

### **Summary Table: Java Exception Handling Scenarios**

|Scenario|Behavior|
|---|---|
|**`try`-`catch`-`finally`**|`finally` always executes.|
|**Multiple `try`-`catch`**|Each `try` must have a corresponding `catch` or `finally`.|
|**Single `try`-Multiple `catch`**|First matching `catch` executes.|
|**`try` without `catch`**|Must have `finally`, or compilation error.|
|**Exception in `catch` block**|Unhandled exception crashes the program.|
|**Exception in `finally` block**|Overrides previous exceptions if not handled.|
|**Exception outside `catch`**|Unhandled exception terminates the program.|

Would you like a **custom exception example** to extend this discussion?